Workbook
Name ADEnq: [1]Sheet4!$A$2:$A$3
Name Adstat: [1]Sheet4!$A$5:$A$8
Name Approval: [1]Sheet2!$A$11:$A$13
Name BCSTATUS: [1]Sheet2!$E$7:$E$12
Name Beg_Bal: '[2] Loan schedule - Term 1'!$C$18:$C$497
Name COLLATERAL: [1]Sheet2!$A$20:$A$78
Name COLLATORDSTA: [1]Sheet2!$E$17:$E$18
Name COMMAPP: [1]Sheet4!$B$21:$B$31
Name COMMSTAT: [1]Sheet4!$A$31:$A$36
Name Commtype: [1]Sheet4!$A$15:$A$20
Name End_Bal: '[2] Loan schedule - Term 1'!$I$18:$I$497
Name Extra_Pay: '[2] Loan schedule - Term 1'!$E$18:$E$497
Name Full_Print: '[2] Loan schedule - Term 1'!$A$1:$J$497
Name Header_Row: ROW('[2] Loan schedule - Term 1'!$17:$17)
Name Int: '[2] Loan schedule - Term 1'!$H$18:$H$497
Name Interest_Rate: '[2] Loan schedule - Term 1'!$D$6
Name Last_Row: IF(Values_Entered,Header_Row+Number_of_Payments,Header_Row)
Name Loan_Amount: '[2] Loan schedule - Term 1'!$D$5
Name Loan_Start: '[2] Loan schedule - Term 1'!$D$9
Name Loan_Years: '[2] Loan schedule - Term 1'!$D$7
Name NamedRange1: [1]Sheet2!$A$1:$A$9
Name Num_Pmt_Per_Year: '[2] Loan schedule - Term 1'!$D$8
Name Number_of_Payments: MATCH(0.01,End_Bal,-1)+1
Name Pay_Num: '[2] Loan schedule - Term 1'!$A$18:$A$497
Name Payment_Date: DATE(YEAR(Loan_Start),MONTH(Loan_Start)+Payment_Number,DAY(Loan_Start))
Name Princ: '[2] Loan schedule - Term 1'!$G$18:$G$497
Name Print_Area_Reset: OFFSET(Full_Print,0,0,Last_Row)
Name Role: [1]Sheet2!$E$22:$E$29
Name Sched_Pay: '[2] Loan schedule - Term 1'!$D$18:$D$497
Name Scheduled_Extra_Payments: '[2] Loan schedule - Term 1'!$D$10
Name Scheduled_Monthly_Payment: '[2] Loan schedule - Term 1'!$J$5
Name STATUS1: [1]Sheet2!$C$1:$C$5
Name Total_Pay: '[2] Loan schedule - Term 1'!$F$18:$F$497
Name Values_Entered: IF(Loan_Amount*Interest_Rate*Loan_Years*Loan_Start>0,1,0)
Name yesno: [1]Sheet4!$A$10:$A$11
Name YNNA: [1]Sheet4!$A$10:$A$12
Name ZeePhotoFIle: [1]Sheet2!$A$11:$A$12

Sheet Scorecard matrix
A1: Franchise | B1: Franchisee Name | C1: State | D1: Profile | E1: Tenure | F1: Expiry Date | G1: Ultimate Expiry Date (Including FY18 release) | H1: FY22 unlimited term candidates | I1: Unlimted Term | J1: Annual Turnover (1 Feb 2020 - 31 Jan 2021) | K1: Sales team engagement score | L1: Digisitation | M1: Not in attendance at Roadshow | N1: Workshop Attendance | O1: Reading weekly bulletins(After final reminder) | P1: Customer Nomination | Q1: MPEX allocation | R1: MPEX Usage % (as @ 08102019) | S1: Late with completion of monthly invoicing | T1: Approved vehicle | U1: Vehicle signage (Past 4 years) | V1: Uniform (ordered in past 12months) | W1: HO Insurances | X1: 30th Sept action email (Feedback) | Y1: Engagement with sales team | Z1: Terminated (mutually or otherwise) | AA1: Breach notice served | AB1: Written warning issued | AC1: commentary | AD1: Vaccine | AE1: Booster | AF1: Medical Exemption | AG1: Contingency engaged
A2: Yatala | B2: Michael Mikits | C2: QLD | D2: Investor | E2: 10 | F2: 45323 | G2: 48976 | I2: =VLOOKUP(A2,'Scorecard summary'!A:AB,10,0) -> Yes | J2: =VLOOKUP(A2,'Revenue @ Feb 2021'!A:B,2,0) -> #N/A | K2: =VLOOKUP(A2,'Sales team engagament review'!A:H,2,0) -> 4 | L2: YES | M2: YES | N2: YES | O2: YES | P2: NO | Q2: YES | S2: NO | T2: ? | U2: ? | V2: ? | W2: YES | Y2: =VLOOKUP(A:A,'Sales team engagament review'!$A:$H,2,0) -> 4 | AD2: 2 + cert
A3: Wyong | B3: Dennis Kinchela | C3: NSW | D3: Owner operator | E3: 4 | F3: 44311 | G3: 47963 | I3: =VLOOKUP(A3,'Scorecard summary'!A:AB,10,0) -> Yes | J3: =VLOOKUP(A3,'Revenue @ Feb 2021'!A:B,2,0) -> 64243.24 | K3: =VLOOKUP(A3,'Sales team engagament review'!A:H,2,0) -> 2 | L3: YES | M3: YES | N3: YES | O3: YES | P3: NO | Q3: YES | R3: =VLOOKUP(A3,'Franchisee Ranking'!B:G,6,0) -> 0 | S3: NO | T3: YES | U3: YES | V3: ? | W3: YES | X3: Had some personal relationship issues but motivated to get MPEX into his customers | Y3: =VLOOKUP(A:A,'Sales team engagament review'!$A:$H,2,0) -> 2 | AD3: 2 + cert
A4: Willoughby | B4: Peter Hayes | C4: NSW | D4: Owner operator | E4: =VLOOKUP(A4,[3]ActiveFranchiseesResults465!$C:$AA,25,0) -> 11 | F4: 43586 | G4: 45413 | I4: =VLOOKUP(A4,'Scorecard summary'!A:AB,10,0) -> Yes | J4: =VLOOKUP(A4,'Revenue @ Feb 2021'!A:B,2,0) -> 167507.73 | K4: =VLOOKUP(A4,'Sales team engagament review'!A:H,2,0) -> 5 | L4: YES | M4: YES | N4: YES | O4: YES | P4: YES | Q4: YES | R4: =VLOOKUP(A4,'Franchisee Ranking'!B:H,6,0) -> 0.23611111 | S4: NO | T4: YES | U4: YES | V4: ? | W4: YES | Y4: =VLOOKUP(A:A,'Sales team engagament review'!$A:$H,2,0) -> 5 | AD4: 2 + cert
A5: Wetherill Park | B5: Madhukar Prasad | C5: NSW | D5: Owner operator | E5: =VLOOKUP(A5,[3]ActiveFranchiseesResults465!$C:$AA,25,0) -> 19 | F5: 45455 | G5: 45820 | I5: =VLOOKUP(A5,'Scorecard summary'!A:AB,10,0) -> Yes | J5: =VLOOKUP(A5,'Revenue @ Feb 2021'!A:B,2,0) -> 168688.02 | K5: =VLOOKUP(A5,'Sales team engagament review'!A:H,2,0) -> 2 | L5: YES | M5: YES | N5: YES | O5: YES | P5: NO | Q5: YES | R5: =VLOOKUP(A5,'Franchisee Ranking'!B:G,6,0) -> 0 | S5: NO | T5: YES | U5: YES | V5: ? | W5: YES | X5: Waiting on Stacey to provide feedback on his migration call down…. | Y5: =VLOOKUP(A:A,'Sales team engagament review'!$A:$H,2,0) -> 2 | AD5: 2 + cert
A6: West Perth | B6: Jobin Mathew Parthickal | C6: WA | D6: Owner operator | E6: =VLOOKUP(A6,[3]ActiveFranchiseesResults465!$C:$AA,25,0) -> 3 | F6: 43709 | G6: 47362 | I6: =VLOOKUP(A6,'Scorecard summary'!A:AB,10,0) -> Yes | J6: =VLOOKUP(A6,'Revenue @ Feb 2021'!A:B,2,0) -> 40896.48 | K6: =VLOOKUP(A6,'Sales team engagament review'!A:H,2,0) -> 3 | L6: NO | M6: YES | N6: YES | O6: YES | P6: NO | Q6: NO | R6: =VLOOKUP(A6,'Franchisee Ranking'!B:G,6,0) -> 0 | S6: NO | T6: ? | U6: ? | V6: Yes | W6: YES | X6: Will allocate to customers ASAP | Y6: =VLOOKUP(A:A,'Sales team engagament review'!$A:$H,2,0) -> 3 | AB6: Yes
A7: Welshpool | B7: Roque Bautista | C7: WA | D7: Owner operator | E7: =VLOOKUP(A7,[3]ActiveFranchiseesResults465!$C:$AA,25,0) -> 5 | F7: 44652 | G7: 48305 | I7: =VLOOKUP(A7,'Scorecard summary'!A:AB,10,0) -> Yes | J7: =VLOOKUP(A7,'Revenue @ Feb 2021'!A:B,2,0) -> 77895.59 | K7: =VLOOKUP(A7,'Sales team engagament review'!A:H,2,0) -> 4 | L7: YES | M7: YES | N7: YES | O7: YES | P7: NO | Q7: YES | R7: =VLOOKUP(A7,'Franchisee Ranking'!B:G,6,0) -> 0.23076923 | S7: NO | T7: ? | U7: ? | V7: ? | W7: YES | Y7: =VLOOKUP(A:A,'Sales team engagament review'!$A:$H,2,0) -> 4 | AD7: 2 + cert
A8: Waterloo | B8: MailPlus Head Office | C8: NSW | D8: N/A | E8: N/A | F8: 44408 | G8: 48060 | I8: HEAD OFFICE | J8: =VLOOKUP(A8,'Revenue @ Feb 2021'!A:B,2,0) -> 65479.59 | K8: =VLOOKUP(A8,'Sales team engagament review'!A:H,2,0) -> #N/A | L8: YES | M8: YES | N8: YES | O8: YES | P8: NO | Q8: YES | R8: =VLOOKUP(A8,'Franchisee Ranking'!B:H,6,0) -> 0.44736842 | S8: NO | T8: ? | U8: ? | V8: ? | W8: NO | Y8: =VLOOKUP(A:A,'Sales team engagament review'!$A:$H,2,0) -> #N/A
A9: Trinh TRINH | B9: Quan Trin | C9: QLD | D9: Owner operator | E9: =VLOOKUP(A9,[3]ActiveFranchiseesResults465!$C:$AA,25,0) -> 16 | F9: 43709 | G9: 46997 | H9: Yes on exit | I9: =VLOOKUP(A9,'Scorecard summary'!A:AB,10,0) -> NO | J9: =VLOOKUP(A9,'Revenue @ Feb 2021'!A:B,2,0) -> 110576.14 | K9: =VLOOKUP(A9,'Sales team engagament review'!A:H,2,0) -> 1 | L9: YES | M9: YES | N9: YES | O9: YES | P9: YES | Q9: YES | R9: =VLOOKUP(A9,'Franchisee Ranking'!B:G,6,0) -> 0 | S9: NO | T9: ? | U9: ? | V9: ? | W9: YES | Y9: =VLOOKUP(A:A,'Sales team engagament review'!$A:$H,2,0) -> 1 | AD9: 2 + cert
A10: Townsville (HO Owned) | B10: MailPlus Head Office | C10: QLD | D10: N/A | E10: N/A | F10: N/A | G10: N/A | I10: =VLOOKUP(A10,'Scorecard summary'!A:AB,10,0) -> HEAD OFFICE | J10: =VLOOKUP(A10,'Revenue @ Feb 2021'!A:B,2,0) -> #N/A | K10: =VLOOKUP(A10,'Sales team engagament review'!A:H,2,0) -> 5 | L10: YES | M10: YES | N10: YES | O10: YES | P10: NO | Q10: NO | S10: NO | T10: ? | U10: ? | V10: ? | W10: NO | Y10: =VLOOKUP(A:A,'Sales team engagament review'!$A:$H,2,0) -> 5
A11: Toowoomba | B11: Kiely Prendergast | C11: QLD | D11: Investor | E11: =VLOOKUP(A11,[3]ActiveFranchiseesResults465!$C:$AA,25,0) -> 3 | F11: 44805 | G11: 46661 | I11: yes | J11: =VLOOKUP(A11,'Revenue @ Feb 2021'!A:B,2,0) -> 149881.33 | K11: =VLOOKUP(A11,'Sales team engagament review'!A:H,2,0) -> 3 | L11: YES | M11: YES | N11: YES | O11: YES | P11: YES | Q11: YES | R11: =VLOOKUP(A11,'Franchisee Ranking'!B:H,6,0) -> 0.13513514 | S11: NO | T11: YES | U11: YES | V11: Yes | W11: NO | Y11: =VLOOKUP(A:A,'Sales team engagament review'!$A:$H,2,0) -> 3 | AD11: 1 + cert
A12: Taren Point | B12: Miljenko Ivanic | C12: NSW | D12: Owner operator | E12: =VLOOKUP(A12,[3]ActiveFranchiseesResults465!$C:$AA,25,0) -> 10 | F12: 43891 | G12: 46447 | I12: =VLOOKUP(A12,'Scorecard summary'!A:AB,10,0) -> yes | J12: =VLOOKUP(A12,'Revenue @ Feb 2021'!A:B,2,0) -> 99485.92 | K12: =VLOOKUP(A12,'Sales team engagament review'!A:H,2,0) -> 4 | L12: YES | M12: YES | N12: YES | O12: YES | P12: YES | Q12: YES | R12: =VLOOKUP(A12,'Franchisee Ranking'!B:H,6,0) -> 0.33333333 | S12: NO | T12: ? | U12: ? | V12: ? | W12: YES | Y12: =VLOOKUP(A:A,'Sales team engagament review'!$A:$H,2,0) -> 4 | AD12: 2 + cert
A13: Tappenden Tappenden | B13: Allison Tappenden | C13: QLD | D13: Owner operator | E13: =VLOOKUP(A13,[3]ActiveFranchiseesResults465!$C:$AA,25,0) -> 16 | F13: 43709 | G13: 46997 | I13: =VLOOKUP(A13,'Scorecard summary'!A:AB,10,0) -> Yes | J13: =VLOOKUP(A13,'Revenue @ Feb 2021'!A:B,2,0) -> 195336.58 | K13: =VLOOKUP(A13,'Sales team engagament review'!A:H,2,0) -> 3 | L13: NO | M13: YES | N13: NO | O13: YES | P13: NO | Q13: NO | R13: =VLOOKUP(A13,'Franchisee Ranking'!B:G,6,0) -> 0 | S13: NO | T13: yES | U13: yES | V13: yes | W13: YES | X13: Hostile reply - blaming anyone & everyone | Y13: =VLOOKUP(A:A,'Sales team engagament review'!$A:$H,2,0) -> 3 | AD13: 2 + cert
A14: Sydney - South East B Sydney - South East B | B14: Ali Gasham | C14: NSW | D14: Investor | E14: =VLOOKUP(A14,[3]ActiveFranchiseesResults465!$C:$AA,25,0) -> 9 | F14: 44470 | G14: 46296 | H14: =I14 -> Yes | I14: =I13 -> Yes | J14: =VLOOKUP(A14,'Revenue @ Feb 2021'!A:B,2,0) -> 208210.4 | K14: =VLOOKUP(A14,'Sales team engagament review'!A:H,2,0) -> 5 | L14: YES | M14: YES | N14: YES | O14: YES | P14: NO | Q14: YES | R14: =VLOOKUP(A14,'Franchisee Ranking'!B:G,6,0) -> 0.074626866 | S14: NO | T14: ? | U14: ? | V14: Yes | W14: YES | X14: Never had big product sales in CBD with AP | Y14: =VLOOKUP(A:A,'Sales team engagament review'!$A:$H,2,0) -> 5 | AD14: 2 + cert
A15: Sydney - South East A Sydney - South East A | B15: Ali Gasham | C15: NSW | D15: Investor | E15: =VLOOKUP(A15,[3]ActiveFranchiseesResults465!$C:$AA,25,0) -> 8 | F15: 42916 | G15: 46568 | H15: =I15 -> Yes payment still O/S | I15: Yes payment still O/S | J15: =VLOOKUP(A15,'Revenue @ Feb 2021'!A:B,2,0) -> 186746.07 | K15: =VLOOKUP(A15,'Sales team engagament review'!A:H,2,0) -> 5 | L15: YES | M15: YES | N15: YES | O15: YES | P15: NO | Q15: YES | R15: =VLOOKUP(A15,'Franchisee Ranking'!B:G,6,0) -> 0.028985507 | S15: NO | T15: ? | U15: ? | V15: Yes | W15: YES | X15: Never had big product sales in CBD with AP | Y15: =VLOOKUP(A:A,'Sales team engagament review'!$A:$H,2,0) -> 5 | AD15: 2 + cert
A16: Sydney - North West | B16: Jason Yang | C16: NSW | D16: Investor | E16: =VLOOKUP(A16,[3]ActiveFranchiseesResults465!$C:$AA,25,0) -> 1 | F16: 44470 | G16: 46296 | I16: =VLOOKUP(A16,'Scorecard summary'!A:AB,10,0) -> Yes | J16: =VLOOKUP(A16,'Revenue @ Feb 2021'!A:B,2,0) -> 273657.43 | K16: =VLOOKUP(A16,'Sales team engagament review'!A:H,2,0) -> 3 | L16: NO | M16: YES | N16: YES | O16: YES | P16: NO | Q16: YES | R16: =VLOOKUP(A16,'Franchisee Ranking'!B:G,6,0) -> 0.03125 | S16: Yes | T16: ? | U16: ? | V16: Yes | W16: YES | X16: Now that LPO margins have been slashed he will embrace | Y16: =VLOOKUP(A:A,'Sales team engagament review'!$A:$H,2,0) -> 3 | AD16: 2 + Cert
A17: Sydney - 2N3 | B17: Gavin Ye | C17: NSW | D17: Investor | E17: =VLOOKUP(A17,[3]ActiveFranchiseesResults465!$C:$AA,25,0) -> 3 | F17: 44470 | G17: 48580 | H17: Yes | I17: =VLOOKUP(A17,'Scorecard summary'!A:AB,10,0) -> NO | J17: =VLOOKUP(A17,'Revenue @ Feb 2021'!A:B,2,0) -> 332842.65 | K17: =VLOOKUP(A17,'Sales team engagament review'!A:H,2,0) -> 4 | L17: YES | M17: NO | N17: YES | O17: YES | P17: NO | Q17: YES | R17: =VLOOKUP(A17,'Franchisee Ranking'!B:G,6,0) -> 0.062068966 | S17: Yes | T17: ? | U17: ? | V17: Yes | W17: YES | X17: Overseas & not readings comms. | Y17: =VLOOKUP(A:A,'Sales team engagament review'!$A:$H,2,0) -> 4 | AA17: Yes | AB17: Yes | AC17: Statutory contractor obligations not being met | AD17: 2 + Cert
A18: Surry Hills | B18: Rodney Eastment | C18: NSW | D18: Owner operator | E18: =VLOOKUP(A18,[3]ActiveFranchiseesResults465!$C:$AA,25,0) -> 11 | F18: 43617 | G18: 46905 | I18: =VLOOKUP(A18,'Scorecard summary'!A:AB,10,0) -> Yes | J18: =VLOOKUP(A18,'Revenue @ Feb 2021'!A:B,2,0) -> 98271.42 | K18: =VLOOKUP(A18,'Sales team engagament review'!A:H,2,0) -> 5 | L18: YES | M18: YES | N18: YES | O18: YES | P18: YES | Q18: NO | R18: =VLOOKUP(A18,'Franchisee Ranking'!B:H,6,0) -> 0.021276596 | S18: NO | T18: YES | U18: YES | V18: ? | W18: YES | Y18: =VLOOKUP(A:A,'Sales team engagament review'!$A:$H,2,0) -> 5 | AD18: 2 + cert
A19: Sunshine Coast | B19: Kiely Prendergast | C19: QLD | D19: Investor | E19: =VLOOKUP(A19,[3]ActiveFranchiseesResults465!$C:$AA,25,0) -> 2 | F19: 45078 | G19: 46843 | I19: yes | J19: =VLOOKUP(A19,'Revenue @ Feb 2021'!A:B,2,0) -> 147084 | K19: =VLOOKUP(A19,'Sales team engagament review'!A:H,2,0) -> 2 | L19: YES | M19: YES | N19: YES | O19: YES | P19: YES | Q19: YES | R19: =VLOOKUP(A19,'Franchisee Ranking'!B:H,6,0) -> 0 | S19: NO | T19: YES | U19: YES | V19: Yes | W19: NO | Y19: =VLOOKUP(A:A,'Sales team engagament review'!$A:$H,2,0) -> 2 | AD19: 2 + Cert
A20: Sunshine | B20: Peter Bournouisouzis | C20: VIC | D20: Owner operator | E20: =VLOOKUP(A20,[3]ActiveFranchiseesResults465!$C:$AA,25,0) -> 10 | F20: 43951 | G20: 46873 | H20: NO | I20: =VLOOKUP(A20,'Scorecard summary'!A:AB,10,0) -> NO | J20: =VLOOKUP(A20,'Revenue @ Feb 2021'!A:B,2,0) -> 51169.69 | K20: =VLOOKUP(A20,'Sales team engagament review'!A:H,2,0) -> 4 | L20: YES | M20: YES | N20: YES | O20: NO | P20: NO | Q20: YES | R20: =VLOOKUP(A20,'Franchisee Ranking'!B:G,6,0) -> 0.096774194 | S20: NO | T20: ? | U20: ? | V20: ? | W20: YES | Y20: =VLOOKUP(A:A,'Sales team engagament review'!$A:$H,2,0) -> 4 | AD20: 2 + cert
A21: Stafford | B21: Michael Mikits | C21: QLD | D21: Investor | E21: 10 | F21: 44256 | G21: 48611 | I21: =VLOOKUP(A21,'Scorecard summary'!A:AB,10,0) -> Yes | J21: =VLOOKUP(A21,'Revenue @ Feb 2021'!A:B,2,0) -> #N/A | K21: =VLOOKUP(A21,'Sales team engagament review'!A:H,2,0) -> 4 | L21: NO | M21: YES | N21: YES | O21: YES | P21: NO | Q21: YES | S21: NO | T21: ? | U21: ? | V21: ? | W21: NO | Y21: =VLOOKUP(A:A,'Sales team engagament review'!$A:$H,2,0) -> 4 | AD21: 2 + cert
A22: St Marys | B22: Jeshnil Prasad | C22: NSW | D22: Owner operator | E22: =VLOOKUP(A22,[3]ActiveFranchiseesResults465!$C:$AA,25,0) -> 11 | F22: 43866 | G22: 45693 | I22: =VLOOKUP(A22,'Scorecard summary'!A:AB,10,0) -> Yes | J22: =VLOOKUP(A22,'Revenue @ Feb 2021'!A:B,2,0) -> 124192.48 | K22: =VLOOKUP(A22,'Sales team engagament review'!A:H,2,0) -> 2 | L22: YES | M22: YES | N22: YES | O22: NO | P22: NO | Q22: YES | R22: =VLOOKUP(A22,'Franchisee Ranking'!B:G,6,0) -> 0.015384615 | S22: NO | T22: ? | U22: ? | V22: ? | W22: YES | X22: Looking to exit - postive about MPEX though | Y22: =VLOOKUP(A:A,'Sales team engagament review'!$A:$H,2,0) -> 2
A23: St Kilda Road | B23: Zhao Yang Lin | C23: VIC | D23: Owner operator | E23: =VLOOKUP(A23,[3]ActiveFranchiseesResults465!$C:$AA,25,0) -> 16 | F23: 43847 | G23: 46769 | I23: =VLOOKUP(A23,'Scorecard summary'!A:AB,10,0) -> Yes | J23: =VLOOKUP(A23,'Revenue @ Feb 2021'!A:B,2,0) -> 91613.22 | K23: =VLOOKUP(A23,'Sales team engagament review'!A:H,2,0) -> 4 | L23: YES | M23: YES | N23: YES | O23: YES | P23: YES | Q23: YES | R23: =VLOOKUP(A23,'Franchisee Ranking'!B:H,6,0) -> 0.22222222 | S23: NO | T23: ? | U23: ? | V23: Yes | W23: YES | Y23: =VLOOKUP(A:A,'Sales team engagament review'!$A:$H,2,0) -> 4 | AD23: 2 + cert
A24: Springwood | B24: Rick Zammit | C24: QLD | D24: Owner operator | E24: =VLOOKUP(A24,[3]ActiveFranchiseesResults465!$C:$AA,25,0) -> 12 | F24: 45139 | G24: 46966 | I24: =VLOOKUP(A24,'Scorecard summary'!A:AB,10,0) -> yes | J24: =VLOOKUP(A24,'Revenue @ Feb 2021'!A:B,2,0) -> 113282.92 | K24: =VLOOKUP(A24,'Sales team engagament review'!A:H,2,0) -> 5 | L24: YES | M24: YES | N24: YES | O24: YES | P24: NO | Q24: NO | R24: =VLOOKUP(A24,'Franchisee Ranking'!B:G,6,0) -> 0 | S24: NO | T24: ? | U24: ? | V24: ? | W24: YES | Y24: =VLOOKUP(A:A,'Sales team engagament review'!$A:$H,2,0) -> 5 | AD24: Still pending
A25: Spring Hill | B25: Michael Mikits | C25: QLD | D25: Investor | E25: 10 | F25: 44621 | G25: 48611 | I25: =VLOOKUP(A25,'Scorecard summary'!A:AB,10,0) -> Yes | J25: =VLOOKUP(A25,'Revenue @ Feb 2021'!A:B,2,0) -> #N/A | K25: =VLOOKUP(A25,'Sales team engagament review'!A:H,2,0) -> 4 | L25: NO | M25: YES | N25: YES | O25: YES | P25: NO | Q25: YES | S25: NO | T25: ? | U25: ? | V25: Yes | W25: NO | Y25: =VLOOKUP(A:A,'Sales team engagament review'!$A:$H,2,0) -> 4 | AD25: 2 + cert
A26: South Melbourne | B26: Dane McGreevy | C26: VIC | D26: Owner operator | E26: =VLOOKUP(A26,[3]ActiveFranchiseesResults465!$C:$AA,25,0) -> 8 | F26: 43738 | G26: 45534 | H26: Yes on exit | I26: =VLOOKUP(A26,'Scorecard summary'!A:AB,10,0) -> NO | J26: =VLOOKUP(A26,'Revenue @ Feb 2021'!A:B,2,0) -> 89442.62 | K26: =VLOOKUP(A26,'Sales team engagament review'!A:H,2,0) -> 5 | L26: YES | M26: YES | N26: YES | O26: YES | P26: NO | Q26: YES | R26: =VLOOKUP(A26,'Franchisee Ranking'!B:G,6,0) -> 0.054545455 | S26: NO | T26: ? | U26: ? | V26: ? | W26: YES | Y26: =VLOOKUP(A:A,'Sales team engagament review'!$A:$H,2,0) -> 5 | AD26: Yes no cert provided
A27: South Bank | B27: Jason Baldwin | C27: QLD | D27: Owner operator | E27: =VLOOKUP(A27,[3]ActiveFranchiseesResults465!$C:$AA,25,0) -> 13 | F27: 44774 | G27: 45870 | I27: =VLOOKUP(A27,'Scorecard summary'!A:AB,10,0) -> Yes | J27: =VLOOKUP(A27,'Revenue @ Feb 2021'!A:B,2,0) -> 175332.66 | K27: =VLOOKUP(A27,'Sales team engagament review'!A:H,2,0) -> 2 | L27: NO | M27: YES | N27: NO | O27: YES | P27: YES | Q27: YES | R27: =VLOOKUP(A27,'Franchisee Ranking'!B:G,6,0) -> 0.056818182 | S27: Yes | T27: YES | U27: yES | V27: ? | W27: YES | X27: No reply | Y27: =VLOOKUP(A:A,'Sales team engagament review'!$A:$H,2,0) -> 2 | AC27: Issue over QLD X-ray, now solved! | AD27: 2 + cert
A28: Silverwater | B28: Paul Harrison | C28: NSW | D28: Investor | E28: =VLOOKUP(A28,[3]ActiveFranchiseesResults465!$C:$AA,25,0) -> 9 | F28: 43994 | G28: 45820 | I28: =VLOOKUP(A28,'Scorecard summary'!A:AB,10,0) -> Yes | J28: =VLOOKUP(A28,'Revenue @ Feb 2021'!A:B,2,0) -> 90340.22 | K28: =VLOOKUP(A28,'Sales team engagament review'!A:H,2,0) -> 3 | L28: YES | M28: YES | N28: YES | O28: YES | P28: NO | Q28: YES | R28: =VLOOKUP(A28,'Franchisee Ranking'!B:G,6,0) -> 0.13333333 | S28: NO | T28: ? | U28: ? | V28: ? | W28: YES | X28: Been waiting on sales support…..... | Y28: =VLOOKUP(A:A,'Sales team engagament review'!$A:$H,2,0) -> 3 | AD28: 2 + cert
A29: Seven Hills | B29: Nhi (David) Lam | C29: NSW | D29: Owner operator | E29: =VLOOKUP(A29,[3]ActiveFranchiseesResults465!$C:$AA,25,0) -> 5 | F29: 44470 | G29: 48122 | I29: =VLOOKUP(A29,'Scorecard summary'!A:AB,10,0) -> Yes | J29: =VLOOKUP(A29,'Revenue @ Feb 2021'!A:B,2,0) -> 68161.14 | K29: =VLOOKUP(A29,'Sales team engagament review'!A:H,2,0) -> 3 | L29: YES | M29: NO | N29: YES | O29: NO | P29: NO | Q29: YES | R29: =VLOOKUP(A29,'Franchisee Ranking'!B:G,6,0) -> 0.1025641 | S29: NO | T29: ? | U29: ? | V29: Yes | W29: YES | Y29: =VLOOKUP(A:A,'Sales team engagament review'!$A:$H,2,0) -> 3 | AD29: 2 + cert
A30: Seaford | B30: Ian Kenna | C30: VIC | D30: Owner operator | E30: 2 | F30: 45020 | G30: 46847 | I30: =VLOOKUP(A30,'Scorecard summary'!A:AB,10,0) -> Yes | J30: =VLOOKUP(A30,'Revenue @ Feb 2021'!A:B,2,0) -> 81796.28 | K30: =VLOOKUP(A30,'Sales team engagament review'!A:H,2,0) -> 4 | L30: YES | M30: YES | N30: YES | O30: YES | P30: YES | Q30: YES | R30: =VLOOKUP(A30,'Franchisee Ranking'!B:H,6,0) -> 0.19607843 | S30: NO | T30: ? | U30: ? | V30: Yes | W30: YES | Y30: =VLOOKUP(A:A,'Sales team engagament review'!$A:$H,2,0) -> 4 | AD30: 2 + cert
A31: Scoresby | B31: David Kosky | C31: VIC | D31: Owner operator | E31: =VLOOKUP(A31,[3]ActiveFranchiseesResults465!$C:$AA,25,0) -> 15 | F31: 43692 | G31: 45519 | I31: =VLOOKUP(A31,'Scorecard summary'!A:AB,10,0) -> Yes | J31: =VLOOKUP(A31,'Revenue @ Feb 2021'!A:B,2,0) -> 96589.66 | K31: =VLOOKUP(A31,'Sales team engagament review'!A:H,2,0) -> 5 | L31: YES | M31: YES | N31: YES | O31: YES | P31: NO | Q31: YES | R31: =VLOOKUP(A31,'Franchisee Ranking'!B:G,6,0) -> 0.60465116 | S31: NO | T31: YES | U31: YES | V31: Yes | W31: NO | Y31: =VLOOKUP(A:A,'Sales team engagament review'!$A:$H,2,0) -> 5 | AD31: Representation given
A32: Salisbury | B32: James Ng | C32: QLD | D32: Owner operator | E32: =VLOOKUP(A32,[3]ActiveFranchiseesResults465!$C:$AA,25,0) -> 3 | F32: 45152 | G32: 46979 | I32: =VLOOKUP(A32,'Scorecard summary'!A:AB,10,0) -> Yes | J32: =VLOOKUP(A32,'Revenue @ Feb 2021'!A:B,2,0) -> 65584.96 | K32: =VLOOKUP(A32,'Sales team engagament review'!A:H,2,0) -> 3 | L32: YES | M32: YES | N32: YES | O32: YES | P32: YES | Q32: YES | R32: =VLOOKUP(A32,'Franchisee Ranking'!B:H,6,0) -> 0.085714286 | S32: NO | T32: YES | U32: YES | V32: ? | W32: YES | X32: No reply | Y32: =VLOOKUP(A:A,'Sales team engagament review'!$A:$H,2,0) -> 3
A33: Ryde | B33: John Chan | C33: NSW | D33: Owner operator | E33: =VLOOKUP(A33,[3]ActiveFranchiseesResults465!$C:$AA,25,0) -> 9 | F33: 43909 | G33: 46831 | I33: =VLOOKUP(A33,'Scorecard summary'!A:AB,10,0) -> yes | J33: =VLOOKUP(A33,'Revenue @ Feb 2021'!A:B,2,0) -> 212340.88 | K33: =VLOOKUP(A33,'Sales team engagament review'!A:H,2,0) -> 4 | L33: YES | M33: YES | N33: YES | O33: YES | P33: NO | Q33: YES | R33: =VLOOKUP(A33,'Franchisee Ranking'!B:G,6,0) -> 0.24210526 | S33: NO | T33: ? | U33: ? | V33: ? | W33: YES | Y33: =VLOOKUP(A:A,'Sales team engagament review'!$A:$H,2,0) -> 4 | AD33: 2 + cert
A34: Rouse Hill | B34: Animesh Castgir | C34: NSW | D34: Owner operator | E34: =VLOOKUP(A34,[3]ActiveFranchiseesResults465!$C:$AA,25,0) -> 2 | F34: 45597 | G34: 45169 | H34: NO | I34: =VLOOKUP(A34,'Scorecard summary'!A:AB,10,0) -> NO | J34: =VLOOKUP(A34,'Revenue @ Feb 2021'!A:B,2,0) -> 42093.45 | K34: =VLOOKUP(A34,'Sales team engagament review'!A:H,2,0) -> 4 | L34: YES | M34: YES | N34: YES | O34: YES | P34: NO | Q34: YES | R34: =VLOOKUP(A34,'Franchisee Ranking'!B:G,6,0) -> 0.23809524 | S34: NO | T34: ? | U34: ? | V34: Yes | W34: YES | Y34: =VLOOKUP(A:A,'Sales team engagament review'!$A:$H,2,0) -> 4 | AD34: 2 + cert
A35: Rosebery | B35: MailPlus Head Office | C35: NSW | D35: N/A | E35: N/A | F35: 44276 | G35: 47928 | I35: HEAD OFFICE | J35: =VLOOKUP(A35,'Revenue @ Feb 2021'!A:B,2,0) -> 40915.75 | K35: =VLOOKUP(A35,'Sales team engagament review'!A:H,2,0) -> 0 | L35: YES | M35: YES | N35: YES | O35: YES | P35: NO | Q35: YES | R35: =VLOOKUP(A35,'Franchisee Ranking'!B:G,6,0) -> 0.16666667 | S35: NO | T35: ? | U35: ? | V35: ? | W35: YES | Y35: =VLOOKUP(A:A,'Sales team engagament review'!$A:$H,2,0) -> 0
A36: Rocklea | B36: Matthew Smith | C36: QLD | D36: Owner operator | E36: =VLOOKUP(A36,[3]ActiveFranchiseesResults465!$C:$AA,25,0) -> 13 | F36: 44803 | G36: 46629 | I36: =VLOOKUP(A36,'Scorecard summary'!A:AB,10,0) -> Yes | J36: =VLOOKUP(A36,'Revenue @ Feb 2021'!A:B,2,0) -> 90218.85 | K36: =VLOOKUP(A36,'Sales team engagament review'!A:H,2,0) -> 5 | L36: YES | M36: YES | N36: YES | O36: YES | P36: NO | Q36: YES | R36: =VLOOKUP(A36,'Franchisee Ranking'!B:G,6,0) -> 0.17073171 | S36: NO | T36: ? | U36: ? | V36: Yes | W36: YES | Y36: =VLOOKUP(A:A,'Sales team engagament review'!$A:$H,2,0) -> 5 | AD36: 2 + cert
A37: Rockhampton (HO Operated/owned) | B37: MailPlus Head Office | C37: QLD | D37: N/A | E37: N/A | F37: N/A | G37: N/A | I37: =VLOOKUP(A37,'Scorecard summary'!A:AB,10,0) -> HEAD OFFICE | J37: =VLOOKUP(A37,'Revenue @ Feb 2021'!A:B,2,0) -> #N/A | K37: =VLOOKUP(A37,'Sales team engagament review'!A:H,2,0) -> 2 | L37: NO | M37: YES | N37: YES | O37: YES | P37: NO | Q37: NO | S37: NO | T37: ? | U37: ? | V37: ? | W37: YES | Y37: =VLOOKUP(A:A,'Sales team engagament review'!$A:$H,2,0) -> 2
A38: Riverside | B38: Gary Jakubowicz | C38: VIC | D38: Owner operator | E38: =VLOOKUP(A38,[3]ActiveFranchiseesResults465!$C:$AA,25,0) -> 8 | F38: 44572 | G38: 44562 | I38: =VLOOKUP(A38,'Scorecard summary'!A:AB,10,0) -> Yes | J38: =VLOOKUP(A38,'Revenue @ Feb 2021'!A:B,2,0) -> 76344.03 | K38: =VLOOKUP(A38,'Sales team engagament review'!A:H,2,0) -> 2 | L38: YES | M38: YES | N38: YES | O38: YES | P38: NO | Q38: YES | R38: =VLOOKUP(A38,'Franchisee Ranking'!B:G,6,0) -> 0.27906977 | S38: NO | T38: ? | U38: ? | V38: ? | W38: YES | Y38: =VLOOKUP(A:A,'Sales team engagament review'!$A:$H,2,0) -> 2 | AD38: 2 + cert
A39: Regency | B39: Ken Smith / Liz Smith | C39: SA | D39: Owner operator | E39: =VLOOKUP(A39,[3]ActiveFranchiseesResults465!$C:$AA,25,0) -> 10 | F39: 43952 | G39: 43952 | I39: =VLOOKUP(A39,'Scorecard summary'!A:AB,10,0) -> Yes | J39: =VLOOKUP(A39,'Revenue @ Feb 2021'!A:B,2,0) -> 55950.5 | K39: =VLOOKUP(A39,'Sales team engagament review'!A:H,2,0) -> 0 | L39: YES | M39: NO | N39: YES | O39: NO | P39: NO | Q39: NO | R39: =VLOOKUP(A39,'Franchisee Ranking'!B:G,6,0) -> 0 | S39: NO | T39: ? | U39: ? | V39: Yes | W39: YES | Y39: =VLOOKUP(A:A,'Sales team engagament review'!$A:$H,2,0) -> 0 | AD39: 2 + cert
A40: Pyrmont | B40: Budi Nagi | C40: NSW | D40: Investor | E40: =VLOOKUP(A40,[3]ActiveFranchiseesResults465!$C:$AA,25,0) -> 14 | F40: 44442 | G40: 46268 | I40: =VLOOKUP(A40,'Scorecard summary'!A:AB,10,0) -> Yes | J40: =VLOOKUP(A40,'Revenue @ Feb 2021'!A:B,2,0) -> 176495.12 | K40: =VLOOKUP(A40,'Sales team engagament review'!A:H,2,0) -> 4 | L40: NO | M40: YES | N40: YES | O40: YES | P40: YES | Q40: YES | R40: =VLOOKUP(A40,'Franchisee Ranking'!B:G,6,0) -> 0 | S40: NO | T40: ? | U40: ? | V40: ? | W40: YES | X40: No reply | Y40: =VLOOKUP(A:A,'Sales team engagament review'!$A:$H,2,0) -> 4 | AA40: Yes | AB40: Yes | AC40: non completion of digitization task | AD40: 2 + cert
...

Sheet Sheet8
A1: MP Nerang – Service Summary - week ending 2nd Jan 2026
A3: Customer | B3: Service Days | C3: Service Type | D3: Timing Notes | E3: Additional Notes
A4: Department of Transport & Main Roads | B4: Friday | C4: Po Box Mail Delivery | D4: Anytime | E4: N/A
A5: Allambe(Funeral) | B5: Tue, Wed & Fri | C5: PO Box Mail delivery & outgoing collection at same time | D5: =D4 -> Anytime | E5: Antonnete doesn't typically arrive until late aternoon
A6: Community Housing | B6: Friday | C6: Mail | D6: =D5 -> Anytime
A7: Stratco | B7: Wednesday & Friday | C7: Banking – Westpac | D7: Anytime | E7: May require change order
A8: Rodd & Gunn (Harbour Town) | B8: Wednesday & Friday | C8: Banking – ANZ | D8: Anytime | E8: May require change order

Sheet Sheet7
A1: Franchise Location | B1: Key Date(s) | C1: Action Taken | D1: Amount Paid / Received | E1: Status / Outcome
A2: MP Penrith | B2: 45717 | C2: Deed of surrender – became HO owned & operated | D2: N/A | E2: Sold 1 Jul 2025 for $100,000
A3: MP Riverside | B3: 45382 | C3: Deed of release – payment to exiting franchisee | D3: Paid $65,000 | E3: HO owned & operated until sold 1 Jul 2024 for $150,000

Sheet Sheet4
A1: Coolum Beach Christian College - Sunshine Coast
A2: Coolum Beach Christian College - Sunshine Coast
A3: Coolum Beach Christian College - Sunshine Coast
A4: Coolum Beach Christian College - Sunshine Coast
A5: WSP Australia Pty Limited - Maroochydore
A6: Toowoomba Garden of Remembrance - Invocare

Sheet Sheet3
A1: Franchise | B1: Ultimate Expiry Date (Including FY18 release)
A2: Sydney - 2N3 | B2: 48580
A3: Sunshine | B3: 46873
A4: Penrith | B4: 45717
A5: Northern Beaches | B5: 46935
A6: Milperra | B6: 47026
A7: Mascot | B7: 47928
A8: Hunter Valley | B8: 44786
A9: Campbellfield | B9: 47604
A10: Braeside | B10: 49217
A11: Bowen Hills | B11: 50345
A12: Barton | B12: 47514
A13: Arncliffe | B13: 48274
A14: Altona | B14: 45505

Sheet Sheet2
A1: Sunshine | B1: 46873
A2: Penrith | B2: 45717
A3: Northern Beaches | B3: 46935
A4: Milperra | B4: 47026
A5: Hunter Valley | B5: 44786
A6: Darlinghurst | B6: 47453

Sheet Covid Summary
A3: Row Labels | B3: Count of Franchise | C3: Count of Vaccine
A4: ACT | B4: 3 | C4: 1 | D4: =B4-C4 -> 2 | E4: =D4/B4 -> 0.66666667
A5: NSW | B5: 48 | C5: 39 | D5: =B5-C5 -> 9 | E5: =D5/B5 -> 0.1875
A6: NT | B6: 1 | D6: =B6-C6 -> 1 | E6: =D6/B6 -> 1
A7: QLD | B7: 36 | C7: 24 | D7: =B7-C7 -> 12 | E7: =D7/B7 -> 0.33333333
A8: SA | B8: 2 | C8: 2 | D8: =B8-C8 -> 0 | E8: =D8/B8 -> 0
A9: TAS | B9: 3 | C9: 1 | D9: =B9-C9 -> 2 | E9: =D9/B9 -> 0.66666667
A10: VIC | B10: 26 | C10: 23 | D10: =B10-C10 -> 3 | E10: =D10/B10 -> 0.11538462
A11: WA | B11: 7 | C11: 5 | D11: =B11-C11 -> 2 | E11: =D11/B11 -> 0.28571429
A12: (blank) | D12: =B12-C12 -> 0 | E12: =C12/B12 -> #DIV/0!
A13: Grand Total | B13: 126 | C13: 95 | D13: =B13-C13 -> 31 | E13: =C13/B13 -> 0.75396825

Sheet Operator Vehicle Log
A1: Franchisee | B1: Vehicle Model | C1: Vehicle Year | D1: Vehicle Colour | E1: Signage | F1: Ownership | G1: Rego | H1: Carrier Bargo | I1: Toll Depot Induction | J1: Operator inducted
A2: Acacia Ridge | B2: Suzuki APV | C2: 2014 | D2: white | E2: no | F2: Franchisee | G2: 740TTK
A3: Adelaide | B3: TBC | C3: TBC | D3: TBC | E3: TBC | F3: TBC | G3: TBC
A4: Adelaide CBD | B4: Fiat Doblo | C4: 2018 | D4: Silver | E4: Yes | F4: Franchisee | G4: SO25CAF
A5: Adelaide CBD | B5: subaru XV | C5: 2015 | D5: Silver | E5: no | F5: Driver | G5: S888BAL
A6: Airport West | C6: 2016 | D6: Silver | E6: No | F6: Franchisee | G6: ALA999
A7: Alexandria | B7: VW Transporter | C7: 2008 | D7: Silver | E7: Yes | F7: Franchisee | G7: BGP04Z | H7: N0 | I7: Pending | J7: Steven Maharjan
A8: Alexandria | C8: 2015 | D8: Silver | E8: Yes | F8: Franchisee | G8: CE42MH | H8: N0 | I8: Yes | J8: Hendry Kifa
A9: Altona | B9: caddy | C9: 2016 | D9: Silver | E9: no | F9: Franchisee | G9: 1GX8QY
A10: Arncliffe | C10: 2015 | D10: silver | E10: Yes | F10: Driver | G10: CG63LT | H10: Yes | I10: Yes | J10: Koda
A11: Arncliffe | C11: 2014 | D11: silver | E11: No | F11: Driver | G11: CQI01F | I11: Yes | J11: Natem
A12: Banyo | B12: Hyundai iLoad | C12: 2010 | D12: Silver | E12: Yes | F12: Driver | G12: 022RHB | H12: Yes
A13: Barton
A14: Baulkham Hills | C14: 2014 | D14: Silver | E14: Yes | F14: Driver | G14: JA0057
A15: Bayswater | B15: Honda CRV | C15: 2015 | D15: Grey | E15: no | F15: Franchisee | G15: 1DZ8VA
A16: Bayswater | B16: Corolla | C16: 2009 | D16: Silver | E16: no | F16: Driver | G16: YDH590
A17: Belmont | B17: hyundai Tucson | C17: 2016 | D17: silver | E17: no | F17: Franchisee | H17: Yes
A18: Blacktown | C18: 2017 | D18: Silver Metalic | E18: No | F18: Driver | G18: DQX94E | H18: N0 - Intends to install | I18: Yes
A19: Blacktown | C19: 2015 | D19: White | E19: No | F19: Driver | G19: VYJ67E | H19: N0 | I19: Yes
A20: Bondi Junction
A21: Booval | B21: VW Caddy Maxi | C21: 2014 | D21: Silver | E21: Yes | F21: Franchisee | G21: CG71VH
A22: Botany | B22: caddy | C22: 2018 | D22: silver | E22: yes | F22: Franchisee | I22: Yes | J22: Richard Chang
A23: Botany | B23: Toyota Prius | C23: 2018 | D23: white | E23: no | F23: Franchisee | I23: Yes | J23: Richard Chang
A24: Bowen Hills | B24: Caddy | C24: 2018 | D24: silver | E24: no | F24: Franchisee
A25: Box Hill
A26: Braeside
A27: Brendale | B27: Caddy | C27: 2017 | D27: Silver | E27: no | F27: Franchisee | G27: 762 XJI
A28: Brisbane | B28: VW Caddy | D28: Silver | E28: Yes | F28: Franchisee | G28: 687WAG
A29: Brisbane | B29: VW Caddy | D29: Silver | E29: Yes | F29: Franchisee | G29: 100YPU
A30: Brisbane | B30: VW Caddy | D30: Silver | E30: Yes | F30: Franchisee | G30: 343WFV
A31: Brisbane | B31: VW Caddy | D31: White | E31: Yes | F31: Franchisee | G31: 108ZKE
A32: Brisbane | B32: VW Transporter | D32: White | E32: Yes | F32: Franchisee | G32: 261BH2
A33: Brisbane | B33: VW Caddy | D33: Silver | E33: Yes | F33: Franchisee | G33: 377XTZ
A34: Brisbane | B34: VW Caddy | D34: Silver | E34: Yes | F34: Franchisee | G34: 994WLS
A35: Brisbane | B35: VW Caddy | D35: Silver | E35: Yes | F35: Franchisee | G35: 399ZXG
A36: Brisbane | B36: Hyundai i30 | D36: Silver | E36: Yes | F36: Franchisee | G36: 167WFU
A37: Brisbane | B37: VW Caddy | D37: White | E37: Yes | F37: Franchisee | G37: 835AE2
A38: Brisbane | B38: VW Caddy | D38: White | E38: Yes | F38: Franchisee | G38: 834AE2
A39: Brisbane | B39: VW Caddy | D39: Silver | E39: Yes | F39: Franchisee | G39: 885XGP
A40: Brookvale | B40: Mercede Vitto | C40: 2020 | D40: white | E40: no | F40: Franchisee | G40: EJX90D
...

Sheet Sales team engagament review
A1: Franchise | B1: Score | C1: Prospects? | D1: Engaged / Communicates ? | E1: Follows Instructions ? | F1: Takes on new work? | G1: Embraces the MPEX and broader business visions? | H1: Rep
A3: Altona | B3: 3 | C3: 0 | D3: 0 | E3: 1 | F3: 1 | G3: 1 | H3: David
A4: Barton | B4: 0
A5: Bondi Junction | B5: 4 | C5: 0 | D5: 1 | E5: 1 | F5: 1 | G5: 1 | H5: Kerina
A6: Canberra CBD | B6: 0
A7: North Sydney | B7: 3 | C7: 0 | D7: 1 | E7: 0 | F7: 1 | G7: 1 | H7: Kerina
A8: Darlinghurst | B8: 2 | C8: 0 | D8: 0 | E8: 1 | F8: 1 | G8: 0 | H8: kerina
A9: Hunter Valley | B9: 0 | C9: 0 | D9: 0 | E9: 0 | F9: 0 | G9: 0 | H9: kerina
A10: Lane Cove | B10: 4 | C10: 0 | D10: 1 | E10: 1 | F10: 1 | G10: 1 | H10: kerina
A11: Nerang | B11: 4 | C11: 0 | D11: 1 | E11: 1 | F11: 1 | G11: 1 | H11: Lee
A12: Newcastle | B12: 3 | C12: 0 | D12: 1 | E12: 1 | F12: 1 | G12: 0 | H12: kerina
A13: Perth CBD | B13: 3 | C13: 0 | D13: 0 | E13: 1 | F13: 1 | G13: 1 | H13: Lee
A14: Pyrmont | B14: 4 | C14: 0 | D14: 1 | E14: 1 | F14: 1 | G14: 1 | H14: kerina
A15: Regency | B15: 0
A16: Seven Hills | B16: 3 | C16: 0 | D16: 1 | E16: 1 | F16: 1 | G16: 0 | H16: kerina
A17: South Bank | B17: 2 | C17: 0 | D17: 0 | E17: 1 | F17: 1 | G17: 0 | H17: Lee
A18: Sydney - 2N3 | B18: 4 | C18: 0 | D18: 1 | E18: 1 | F18: 1 | G18: 1 | H18: kerina
A19: Sydney - North West | B19: 3 | C19: 0 | D19: 1 | E19: 0 | F19: 1 | G19: 1 | H19: kerina
A20: Tappenden Tappenden | B20: 3 | C20: 0 | D20: 1 | E20: 1 | F20: 1 | G20: 0 | H20: Lee
A21: West Perth | B21: 3 | C21: 0 | D21: 0 | E21: 1 | F21: 1 | G21: 1 | H21: Lee
A22: Acacia Ridge | B22: 5 | C22: 1 | D22: 1 | E22: 1 | F22: 1 | G22: 1 | H22: Lee
A23: Canberra Airport | B23: 0
A24: Riverside | B24: 2 | C24: 0 | D24: 1 | E24: 1 | F24: 0 | G24: 0 | H24: David
A25: Cairns | B25: 2 | C25: 0 | D25: 0 | E25: 1 | F25: 1 | G25: 0 | H25: Lee
A26: Braeside | B26: 4 | C26: 0 | D26: 1 | E26: 1 | F26: 1 | G26: 1 | H26: David
A27: Brisbane CBD | B27: 4 | C27: 0 | D27: 1 | E27: 1 | F27: 1 | G27: 1 | H27: Lee
A28: Eagle Farm | B28: 4 | C28: 0 | D28: 1 | E28: 1 | F28: 1 | G28: 1 | H28: Lee
A29: Geebung | B29: 4 | C29: 0 | D29: 1 | E29: 1 | F29: 1 | G29: 1 | H29: Lee
A30: Hamilton | B30: 4 | C30: 0 | D30: 1 | E30: 1 | F30: 1 | G30: 1 | H30: Lee
A31: Illawarra | B31: 5 | C31: 1 | D31: 1 | E31: 1 | F31: 1 | G31: 1 | H31: kerina
A32: Spring Hill | B32: 4 | C32: 0 | D32: 1 | E32: 1 | F32: 1 | G32: 1 | H32: Lee
A33: Stafford | B33: 4 | C33: 0 | D33: 1 | E33: 1 | F33: 1 | G33: 1 | H33: Lee
A34: Yatala | B34: 4 | C34: 0 | D34: 1 | E34: 1 | F34: 1 | G34: 1 | H34: Lee
A35: Airport West | B35: 4 | C35: 0 | D35: 1 | E35: 1 | F35: 1 | G35: 1 | H35: David
... A40: Booval | B40: 2 | C40: 0 | D40: 0 | E40: 1 | F40: 0 | G40: 1 | H40: Lee
A41: Botany Botany | B41: 0 | C41: 0
A42: Bowen Hills | B42: 2 | C42: 0 | D42: 0 | E42: 1 | F42: 1 | G42: 0 | H42: Lee
A43: Box Hill | B43: 5 | C43: 1 | D43: 1 | E43: 1 | F43: 1 | G43: 1 | H43: David
A44: Brendale | B44: 4 | C44: 0 | D44: 1 | E44: 1 | F44: 1 | G44: 1 | H44: Lee
A45: Brookvale | B45: 3 | C45: 0 | D45: 1 | E45: 1 | F45: 1 | G45: 0 | H45: kerina
...

Sheet Engaged v Signups
A1: Row Labels | B1: Count | C1: Score
A2: Geelong | B2: 26 | C2: =VLOOKUP(A2,'Sales team engagament review'!A:H,2,0) -> 5
A3: Brisbane | B3: 22 | C3: 5
A4: Melbourne CBD | B4: 21 | C4: =VLOOKUP(A4,'Sales team engagament review'!A:H,2,0) -> 5
A5: Adelaide CBD | B5: 18 | C5: =VLOOKUP(A5,'Sales team engagament review'!A:H,2,0) -> 5
A6: Mailplus Pty Ltd | B6: 11 | C6: HO
A7: Pyrmont | B7: 11 | C7: =VLOOKUP(A7,'Sales team engagament review'!A:H,2,0) -> 4
A8: Sunshine Coast | B8: 11 | C8: =VLOOKUP(A8,'Sales team engagament review'!A:H,2,0) -> 2
A9: Byron Bay | B9: 10 | C9: =VLOOKUP(A9,'Sales team engagament review'!A:H,2,0) -> 5
A10: Willoughby | B10: 10 | C10: =VLOOKUP(A10,'Sales team engagament review'!A:H,2,0) -> 5
A11: Osborne Park | B11: 9 | C11: =VLOOKUP(A11,'Sales team engagament review'!A:H,2,0) -> 5
A12: Gold Coast | B12: 8 | C12: =VLOOKUP(A12,'Sales team engagament review'!A:H,2,0) -> 4
A13: North Lakes | B13: 8 | C13: =VLOOKUP(A13,'Sales team engagament review'!A:H,2,0) -> 4
A14: Sydney - South East A Sydney - South East A | B14: 8 | C14: =VLOOKUP(A14,'Sales team engagament review'!A:H,2,0) -> 5
A15: Taren Point | B15: 8 | C15: =VLOOKUP(A15,'Sales team engagament review'!A:H,2,0) -> 4
A16: Hoppers Crossing | B16: 7 | C16: =VLOOKUP(A16,'Sales team engagament review'!A:H,2,0) -> 4
A17: Bondi Junction | B17: 6 | C17: =VLOOKUP(A17,'Sales team engagament review'!A:H,2,0) -> 4
A18: Box Hill | B18: 6 | C18: =VLOOKUP(A18,'Sales team engagament review'!A:H,2,0) -> 5
... A73: Fairfield | B73: 2 | C73: =VLOOKUP(A73,'Sales team engagament review'!A:H,2,0) -> 3
A74: Ipswich | B74: 2 | C74: HO
A75: Lalor | B75: 2 | C75: =VLOOKUP(A75,'Sales team engagament review'!A:H,2,0) -> 4
A76: Lane Cove | B76: 2 | C76: =VLOOKUP(A76,'Sales team engagament review'!A:H,2,0) -> 4
A77: Lane Lane | B77: 2 | C77: =VLOOKUP(A77,'Sales team engagament review'!A:H,2,0) -> 5
A78: Macquarie Park | B78: 2 | C78: =VLOOKUP(A78,'Sales team engagament review'!A:H,2,0) -> 4
A79: Mascot | B79: 2 | C79: =VLOOKUP(A79,'Sales team engagament review'!A:H,2,0) -> 1
A80: Moorebank | B80: 2 | C80: =VLOOKUP(A80,'Sales team engagament review'!A:H,2,0) -> 4
A81: Morningside | B81: 2 | C81: =VLOOKUP(A81,'Sales team engagament review'!A:H,2,0) -> 4
A82: Mount Gravatt | B82: 2 | C82: =VLOOKUP(A82,'Sales team engagament review'!A:H,2,0) -> 5
A83: Perth CBD | B83: 2 | C83: =VLOOKUP(A83,'Sales team engagament review'!A:H,2,0) -> 3
A84: Salisbury | B84: 2 | C84: =VLOOKUP(A84,'Sales team engagament review'!A:H,2,0) -> 3
A85: Seven Hills | B85: 2 | C85: =VLOOKUP(A85,'Sales team engagament review'!A:H,2,0) -> 3
A86: South Bank | B86: 2 | C86: =VLOOKUP(A86,'Sales team engagament review'!A:H,2,0) -> 2
... A93: Braeside | B93: 1 | C93: =VLOOKUP(A93,'Sales team engagament review'!A:H,2,0) -> 4
A94: Coffs Harbour | B94: 1 | C94: HO
A95: Dandenong | B95: 1 | C95: =VLOOKUP(A95,'Sales team engagament review'!A:H,2,0) -> 3
A96: Epping | B96: 1 | C96: HO
A97: Hallam | B97: 1 | C97: =VLOOKUP(A97,'Sales team engagament review'!A:H,2,0) -> 2
A98: Hobart | B98: 1 | C98: =VLOOKUP(A98,'Sales team engagament review'!A:H,2,0) -> 0
A99: Kewdale | B99: 1 | C99: =VLOOKUP(A99,'Sales team engagament review'!A:H,2,0) -> 0
A100: Liverpool | B100: 1 | C100: =VLOOKUP(A100,'Sales team engagament review'!A:H,2,0) -> 3
...

Sheet Tenure
A1: Internal ID | B1: State | C1: Name | D1: Franchisee | E1: Franchisee First Name | F1: Franchisee Last Name | G1: Billing Address 1 | H1: Billing Address 2 | I1: Billing City | J1: Billing State/Province | K1: Billing Zip | L1: Shipping City | M1: Shipping State/Province | N1: Shipping Zip | O1: Email | P1: Payment Cycle | Q1: Classification | R1: Franchisee Mobile No | S1: Minimum of Commencement Date | T1: Maximum of Cease Date | U1: Sum of Renewals | V1: Exclude From Batch Printing | W1: Company-Owned Territory | X1: ABN | Y1: 43871 | Z1: Duration
A2: 212 | B2: QLD | C2: Acacia Ridge | D2: Acacia Ridge | E2: Rick | F2: Zammit | G2: - None - | H2: 8 Pathfinder Rd | I2: Coomera | J2: QLD | K2: 4209 | L2: Coomera | M2: QLD | N2: 4209 | O2: AcaciaRidge@mailplus.com.au | P2: Weekly | Q2: Current | R2: 0404 314 375 | S2: 39114 | U2: 1 | V2: Yes | W2: No | X2: 78123031345 | Y2: =IF(S2="","",($Y$1-S2)/365) -> 13.032877 | Z2: 13.032877 | AA2: =IF(Z2="","",ROUNDUP(Z2,0)) -> 14
A3: 694179 | B3: SA | C3: Adelaide CBD | D3: Adelaide CBD | E3: Chentelle | F3: Garreffa | G3: - None - | H3: 19 John Ramsay Cct | I3: Hope Valley | J3: SA | K3: 5090 | L3: Hope Valley | M3: SA | N3: 5090 | O3: AdelaideCBD@mailplus.com.au | P3: Weekly | Q3: Current | R3: 405165103 | S3: 43617 | U3: 1 | V3: Yes | W3: No | X3: 62236853451 | Y3: =IF(S3="","",($Y$1-S3)/365) -> 0.69589041 | Z3: 0.69589041 | AA3: =IF(Z3="","",ROUNDUP(Z3,0)) -> 1
A4: 214 | B4: VIC | C4: Airport West | D4: Airport West | E4: Stephen | F4: Begeman | G4: Unit 1 | H4: 175 Bellevue Ave | I4: Rosanna | J4: VIC | K4: 3084 | L4: Rosanna | M4: VIC | N4: 3084 | O4: AirportWest@mailplus.com.au | P4: End of Month | Q4: Current | R4: 408108775 | S4: 38369 | T4: 43569 | U4: 4 | V4: Yes | W4: No | X4: 93446741190 | Y4: =IF(S4="","",($Y$1-S4)/365) -> 15.073973 | Z4: 15.073973 | AA4: =IF(Z4="","",ROUNDUP(Z4,0)) -> 16
A5: 480439 | B5: NSW | C5: Albury | D5: Albury | E5: Michael | F5: Waite | G5: - None - | H5: 10 Sutton Court | I5: Wodonga | J5: VIC | K5: 3690 | L5: Wodonga | M5: VIC | N5: 3690 | O5: albury@mailplus.com.au | P5: Weekly | Q5: Current | R5: 417421505 | S5: 42826 | U5: 1 | V5: Yes | W5: No | X5: 34176889478 | Y5: =IF(S5="","",($Y$1-S5)/365) -> 2.8630137 | Z5: 2.8630137 | AA5: =IF(Z5="","",ROUNDUP(Z5,0)) -> 3
A6: 215 | B6: NSW | C6: Alexandria | D6: Alexandria | E6: Hendry | F6: Kifa | G6: - None - | H6: 9 Culburra Rd | I6: Miranda | J6: NSW | K6: 2228 | L6: Miranda | M6: NSW | N6: 2228 | O6: Alexandria@mailplus.com.au | P6: Fortnightly | Q6: Current | R6: 421311727 | S6: 37271 | T6: 43569 | U6: 6 | V6: Yes | W6: No | X6: 69111538295 | Y6: =IF(S6="","",($Y$1-S6)/365) -> 18.082192 | Z6: 18.082192 | AA6: =IF(Z6="","",ROUNDUP(Z6,0)) -> 19
A7: 216 | B7: VIC | C7: Altona | D7: Altona | E7: Rhofel | F7: De La Cerna | G7: - None - | H7: 110 Bondi Parade | I7: Point Cook | J7: VIC | K7: 3030 | L7: Point Cook | M7: VIC | N7: 3030 | O7: Altona@mailplus.com.au | P7: Weekly | Q7: Current | R7: 0439 927 388 | S7: 38565 | T7: 39995 | U7: 3 | V7: Yes | W7: No | X7: 75288562937 | Y7: =IF(S7="","",($Y$1-S7)/365) -> 14.536986 | Z7: 14.536986 | AA7: =IF(Z7="","",ROUNDUP(Z7,0)) -> 15
A8: 5386 | B8: NSW | C8: Arncliffe | D8: Arncliffe | E8: Ali | F8: Gasham | G8: - None - | H8: 26 Lansdowne St | I8: Bardwell Valley | J8: NSW | K8: 2207 | L8: Bardwell Valley | M8: NSW | N8: 2207 | O8: Arncliffe@mailplus.com.au | P8: Weekly | Q8: Current | R8: 415775710 | S8: 40238 | T8: 42092 | U8: 4 | V8: Yes | W8: No | X8: 36112969007 | Y8: =IF(S8="","",($Y$1-S8)/365) -> 9.9534247 | Z8: 9.9534247 | AA8: =IF(Z8="","",ROUNDUP(Z8,0)) -> 10
A9: 64113 | B9: QLD | C9: Banyo | D9: Banyo | E9: Bob | F9: Schroeder | G9: 29 Stebbing St | H9: - None - | I9: Aspley | J9: QLD | K9: 4034 | L9: Aspley | M9: QLD | N9: 4034 | O9: banyo@mailplus.com.au | P9: Weekly | Q9: Current | R9: 412309686 | S9: 40513 | T9: 41365 | U9: 3 | V9: Yes | W9: No | X9: 81618161922 | Y9: =IF(S9="","",($Y$1-S9)/365) -> 9.2 | Z9: 9.2 | AA9: =IF(Z9="","",ROUNDUP(Z9,0)) -> 10
A10: 249910 | B10: ACT | C10: Barton | D10: Barton | E10: Saffat | F10: Riad | G10: 20/ | H10: 10 Ovens St | I10: Griffith | J10: ACT | K10: 2603 | L10: Griffith | M10: ACT | N10: 2603 | O10: barton@mailplus.com.au | P10: Weekly | Q10: Current | R10: 433168170 | S10: 42036 | U10: 1 | V10: Yes | W10: No | X10: 75151402845 | Y10: =IF(S10="","",($Y$1-S10)/365) -> 5.0273973 | Z10: 5.0273973 | AA10: =IF(Z10="","",ROUNDUP(Z10,0)) -> 6
A11: 143 | B11: NSW | C11: Baulkham Hills | D11: Baulkham Hills | E11: Paul | F11: Harrison | G11: - None - | H11: 6 Janet St | I11: Bass Hill | J11: NSW | K11: 2197 | L11: Bass Hill | M11: NSW | N11: 2197 | O11: BaulkhamHills@mailplus.com.au | P11: Weekly | Q11: Current | R11: 413691109 | S11: 37054 | T11: 43569 | U11: 5 | V11: Yes | W11: No | X11: 27120656833 | Y11: =IF(S11="","",($Y$1-S11)/365) -> 18.676712 | Z11: 18.676712 | AA11: =IF(Z11="","",ROUNDUP(Z11,0)) -> 19
A12: 404282 | B12: VIC | C12: Bayswater | D12: Bayswater | E12: Jayna | F12: Vakil | G12: - None - | H12: 40 Johnson Dr | I12: Ferntree Gully | J12: VIC | K12: 3156 | L12: Ferntree Gully | M12: VIC | N12: 3156 | O12: bayswater@mailplus.com.au | P12: Weekly | Q12: Current | R12: 451878366 | S12: 42583 | U12: 1 | V12: Yes | W12: No | X12: 62101675321 | Y12: =IF(S12="","",($Y$1-S12)/365) -> 3.5287671 | Z12: 3.5287671 | AA12: =IF(Z12="","",ROUNDUP(Z12,0)) -> 4
A13: 293029 | B13: ACT | C13: Belconnen | D13: Belconnen | E13: Raman | F13: Kumar | G13: 12/ | H13: 6 Antis St | I13: Phillip | J13: ACT | K13: 2606 | L13: Phillip | M13: ACT | N13: 2606 | O13: popie.popie@mailplus.com.au | P13: Weekly | Q13: Current | R13: 490234669 | S13: 42248 | U13: 1 | V13: Yes | W13: No | X13: - None - | Y13: =IF(S13="","",($Y$1-S13)/365) -> 4.4465753 | Z13: 4.4465753 | AA13: =IF(Z13="","",ROUNDUP(Z13,0)) -> 5
A14: 452187 | B14: WA | C14: Belmont | D14: Belmont | E14: Roberto | F14: Bautista | G14: - None - | H14: 91 St Kilda Road | I14: Rivervale | J14: WA | K14: 6103 | L14: Rivervale | M14: WA | N14: 6103 | O14: belmont@mailplus.com.au | P14: Weekly | Q14: Current | R14: 419920057 | S14: 42736 | T14: 43501 | U14: 2 | V14: Yes | W14: No | X14: 19934903153 | Y14: =IF(S14="","",($Y$1-S14)/365) -> 3.109589 | Z14: 3.109589 | AA14: =IF(Z14="","",ROUNDUP(Z14,0)) -> 4
A15: 218 | B15: NSW | C15: Blacktown | D15: Blacktown | E15: Rodney | F15: Eastment | G15: PO Box 537 | H15: - None - | I15: Blacktown | J15: NSW | K15: 2148 | L15: Pitt Town | M15: NSW | N15: 2756 | O15: Blacktown@mailplus.com.au | P15: Fortnightly | Q15: Current | R15: 414712661 | S15: 37291 | T15: 43569 | U15: 5 | V15: Yes | W15: No | X15: 98125713804 | Y15: =IF(S15="","",($Y$1-S15)/365) -> 18.027397 | Z15: 18.027397 | AA15: =IF(Z15="","",ROUNDUP(Z15,0)) -> 19
A16: 219 | B16: NSW | C16: Bondi Junction | D16: Bondi Junction | E16: Katy | F16: Brooks | G16: PO Box 1862 | H16: - None - | I16: Bondi Junction | J16: NSW | K16: 1355 | L16: Waverley | M16: NSW | N16: 2024 | O16: BondiJunction@mailplus.com.au | P16: Weekly | Q16: Current | R16: 409774451 | S16: 36941 | T16: 42081 | U16: 5 | V16: Yes | W16: No | X16: 83200463080 | Y16: =IF(S16="","",($Y$1-S16)/365) -> 18.986301 | Z16: 18.986301 | AA16: =IF(Z16="","",ROUNDUP(Z16,0)) -> 19
A17: 453361 | B17: QLD | C17: Booval | D17: Booval | E17: Kiely | F17: Prendergast | G17: - None - | H17: 22 Abbotsford Parade | I17: Abbottsford | J17: NSW | K17: 2046 | L17: Abbottsford | M17: NSW | N17: 2046 | O17: booval@mailplus.com.au | P17: Weekly | Q17: Current | R17: 432741482 | S17: 42370 | U17: 0 | V17: Yes | W17: No | X17: 99725813659 | Y17: =IF(S17="","",($Y$1-S17)/365) -> 4.1123288 | AA17: =IF(Z17="","",ROUNDUP(Z17,0))
A18: 280 | B18: NSW | C18: Botany Botany | D18: Botany | E18: Richard | F18: Chang | G18: - None - | H18: 45 Siandra Dr | I18: Kareela | J18: NSW | K18: 2232 | L18: Kareela | M18: NSW | N18: 2232 | O18: botany@mailplus.com.au | P18: Weekly | Q18: Current | R18: 0423 194 406 | S18: 39326 | T18: 41365 | U18: 4 | V18: Yes | W18: No | X18: 76206465451 | Y18: =IF(S18="","",($Y$1-S18)/365) -> 12.452055 | Z18: 12.452055 | AA18: =IF(Z18="","",ROUNDUP(Z18,0)) -> 13
A19: 575095 | B19: QLD | C19: Bowen Hills | D19: Bowen Hills | E19: Thomas | F19: Williams | G19: - None - | H19: 4/16 Emuglen Place | I19: Ferny Grove, | J19: QLD | K19: 4055 | L19: Ferny Grove, | M19: QLD | N19: 4055 | O19: bowenhills@mailplus.com.au | P19: Weekly | Q19: Current | R19: 412571657 | S19: 43191 | U19: 1 | V19: Yes | W19: No | X19: 89838503515 | Y19: =IF(S19="","",($Y$1-S19)/365) -> 1.8630137 | Z19: 1.8630137 | AA19: =IF(Z19="","",ROUNDUP(Z19,0)) -> 2
A20: 775289 | B20: VIC | C20: Box Hill | D20: Box Hill | E20: Michael | F20: Debnam | G20: - None - | H20: 164 STATION STREET | I20: ASTENDELE | J20: VIC | K20: 3195 | L20: ASTENDELE | M20: VIC | N20: 3195 | O20: boxhill@mailplus.com.au | P20: Weekly | Q20: Current | R20: 413303978 | S20: 42370 | U20: 0 | V20: Yes | W20: No | X20: 42611258354 | Y20: =IF(S20="","",($Y$1-S20)/365) -> 4.1123288 | AA20: =IF(Z20="","",ROUNDUP(Z20,0))
A21: 220 | B21: VIC | C21: Braeside | D21: Braeside | E21: Sally | F21: Skomrlj | G21: - None - | H21: 44 Harbour Dr | I21: Patterson Lakes | J21: VIC | K21: 3197 | L21: Patterson Lakes | M21: VIC | N21: 3197 | O21: Braeside@mailplus.com.au | P21: Fortnightly | Q21: Current | R21: 0400 456 445 | S21: 38261 | T21: 41912 | U21: 3 | V21: Yes | W21: No | X21: 27942103711 | Y21: =IF(S21="","",($Y$1-S21)/365) -> 15.369863 | Z21: 15.369863 | AA21: =IF(Z21="","",ROUNDUP(Z21,0)) -> 16
A22: 511931 | B22: QLD | C22: Brendale | D22: Brendale | E22: Gregory | F22: Hart | G22: - None - | H22: 2 Rafter Ave | I22: Albany Creek | J22: QLD | K22: 4035 | L22: Albany Creek | M22: QLD | N22: 4035 | O22: brendale@mailplus.com.au | P22: Weekly | Q22: Current | R22: 411417645 | S22: 42979 | U22: 1 | V22: Yes | W22: No | X22: 62664141816 | Y22: =IF(S22="","",($Y$1-S22)/365) -> 2.4438356 | Z22: 2.4438356 | AA22: =IF(Z22="","",ROUNDUP(Z22,0)) -> 3
A23: 696179 | B23: QLD | C23: Brisbane | D23: Brisbane | E23: Michael | F23: MIkits | G23: PO Box 221 | H23: - None - | I23: Surfers Paradise | J23: QLD | K23: 4217 | L23: Surfers Paradise | M23: QLD | N23: 4217 | O23: michael@mailplusbrisbane.com.au | P23: Weekly | Q23: Current | R23: 428224516 | S23: 42370 | U23: 0 | V23: Yes | W23: No | X23: 75226391808 | Y23: =IF(S23="","",($Y$1-S23)/365) -> 4.1123288 | AA23: =IF(Z23="","",ROUNDUP(Z23,0))
A24: 322523 | B24: NSW | C24: Brookvale | D24: Brookvale | E24: Zhi Min | F24: Huang | G24: 174 Terry Street | H24: - None - | I24: Connells Point | J24: NSW | K24: 2221 | L24: Connells Point | M24: NSW | N24: 2221 | O24: brookvale@mailplus.com.au | P24: Weekly | Q24: Current | R24: 415805448 | S24: 42339 | T24: 43569 | U24: 2 | V24: Yes | W24: No | X24: 89397691109 | Y24: =IF(S24="","",($Y$1-S24)/365) -> 4.1972603 | Z24: 4.1972603 | AA24: =IF(Z24="","",ROUNDUP(Z24,0)) -> 5
A25: 206118 | B25: QLD | C25: Browns Plains | D25: Browns Plains | E25: David | F25: Connor | G25: 8 Pendennis Place | H25: - None - | I25: Carindale | J25: QLD | K25: 4152 | L25: Carindale | M25: QLD | N25: 4152 | O25: brownsplains@mailplus.com.au | P25: Weekly | Q25: Current | R25: 0497 229 882 | S25: 41487 | T25: 43312 | U25: 3 | V25: Yes | W25: No | X25: 98819709082 | Y25: =IF(S25="","",($Y$1-S25)/365) -> 6.5315068 | Z25: 6.5315068 | AA25: =IF(Z25="","",ROUNDUP(Z25,0)) -> 7
A26: 219412 | B26: QLD | C26: Burleigh | D26: Burleigh | E26: Maria | F26: Hamilton | G26: PO Box 4851 | H26: - None - | I26: Robina Town Centre | J26: QLD | K26: 4230 | L26: Elanora | M26: QLD | N26: 4221 | O26: burleigh@mailplus.com.au | P26: Weekly | Q26: Current | R26: 409417000 | S26: 41708 | T26: 42622 | U26: 2 | V26: Yes | W26: No | X26: 74107357924 | Y26: =IF(S26="","",($Y$1-S26)/365) -> 5.9260274 | Z26: 5.9260274 | AA26: =IF(Z26="","",ROUNDUP(Z26,0)) -> 6
A27: 794958 | B27: NSW | C27: Byron Bay | D27: Byron Bay | E27: Ratu | F27: Clarke | G27: GPO Box 110 | H27: - None - | I27: Byron Bay | J27: NSW | K27: 2481 | L27: Byron Bay | M27: NSW | N27: 2481 | O27: ByronBay@mailplus.com.au | P27: - None - | Q27: Current | R27: 0405 842 669 | S27: 42370 | U27: 0 | V27: No | W27: Yes | X27: 45609801194 | Y27: =IF(S27="","",($Y$1-S27)/365) -> 4.1123288 | AA27: =IF(Z27="","",ROUNDUP(Z27,0))
A28: 404079 | B28: QLD | C28: Cairns | D28: Cairns | E28: Gary | F28: Chapman | G28: 3/ | H28: 95 Davidson St | I28: Port Douglas | J28: QLD | K28: 4877 | L28: Port Douglas | M28: QLD | N28: 4877 | O28: cairns@mailplus.com.au | P28: Weekly | Q28: Current | R28: 466889307 | S28: 42582 | U28: 1 | V28: Yes | W28: No | X28: 90936120329 | Y28: =IF(S28="","",($Y$1-S28)/365) -> 3.5315068 | Z28: 3.5315068 | AA28: =IF(Z28="","",ROUNDUP(Z28,0)) -> 4
A29: 574991 | B29: VIC | C29: Campbellfield | D29: Campbellfield | E29: Scott | F29: McKay | G29: - None - | H29: 3/11 Edmund Street | I29: Maidstone | J29: VIC | K29: 3012 | L29: Maidstone | M29: VIC | N29: 3012 | O29: campbellfield@mailplus.com.au | P29: Weekly | Q29: Current | R29: 423335131 | S29: 42370 | U29: 0 | V29: Yes | W29: No | X29: 19621840480 | Y29: =IF(S29="","",($Y$1-S29)/365) -> 4.1123288 | AA29: =IF(Z29="","",ROUNDUP(Z29,0))
A30: 1415222 | B30: NSW | C30: Campbelltown | D30: Campbelltown | E30: Khushbu P | F30: Davaria | G30: 1/32 Alfred Street | H30: - None - | I30: Granville | J30: NSW | K30: 2142 | L30: Granville | M30: NSW | N30: 2142 | O30: campbelltown@mailplus.com.au | P30: Weekly | Q30: Current | R30: 474707587 | S30: 42370 | U30: 0 | V30: Yes | W30: No | X30: 34643480577 | Y30: =IF(S30="","",($Y$1-S30)/365) -> 4.1123288 | AA30: =IF(Z30="","",ROUNDUP(Z30,0))
A31: 709359 | B31: ACT | C31: Canberra Airport | D31: Canberra Airport | E31: Syed Lutful | F31: Hakim | G31: - None - | H31: 85 Farran Street | I31: Gungahlin | J31: ACT | K31: 2912 | L31: Gungahlin | M31: ACT | N31: 2912 | O31: canberraairport@mailplus.com.au | P31: Weekly | Q31: Current | R31: 469794938 | S31: 42370 | U31: 0 | V31: Yes | W31: No | X31: 35632341818 | Y31: =IF(S31="","",($Y$1-S31)/365) -> 4.1123288 | AA31: =IF(Z31="","",ROUNDUP(Z31,0))
A32: 753283 | B32: ACT | C32: Canberra CBD | D32: Canberra CBD | E32: Michael | F32: McDaid | G32: GPO Box 586 | H32: - None - | I32: Sydney | J32: NSW | K32: 2000 | L32: Sydney | M32: NSW | N32: 2000 | O32: canberracbd@mailplus.com.au | P32: - None - | Q32: Current | R32: 0420 993 117 | S32: 42370 | U32: 0 | V32: No | W32: Yes | X32: 45609801194 | Y32: =IF(S32="","",($Y$1-S32)/365) -> 4.1123288 | AA32: =IF(Z32="","",ROUNDUP(Z32,0))
A33: 92250 | B33: WA | C33: Canning Vale | D33: Canning Vale | E33: Todd | F33: Ingram | G33: - None - | H33: Unit 3, 16 Coojong Link | I33: Success | J33: WA | K33: 6164 | L33: Success | M33: WA | N33: 6164 | O33: canningvale@mailplus.com.au | P33: Weekly | Q33: Current | R33: 412362537 | S33: 41699 | U33: 1 | V33: Yes | W33: No | X33: 28976700862 | Y33: =IF(S33="","",($Y$1-S33)/365) -> 5.9506849 | Z33: 5.9506849 | AA33: =IF(Z33="","",ROUNDUP(Z33,0)) -> 6
A34: 322524 | B34: VIC | C34: Clayton | D34: Clayton | E34: Devinder | F34: Singh | G34: - None - | H34: 23 Curzon Street | I34: Clyde North | J34: VIC | K34: 3978 | L34: Clyde North | M34: VIC | N34: 3978 | O34: clayton@mailplus.com.au | P34: Weekly | Q34: Current | R34: 433410006 | S34: 42309 | U34: 1 | V34: Yes | W34: No | X34: 45407520164 | Y34: =IF(S34="","",($Y$1-S34)/365) -> 4.2794521 | Z34: 4.2794521 | AA34: =IF(Z34="","",ROUNDUP(Z34,0)) -> 5
A35: 618658 | B35: QLD | C35: Cleveland | D35: Cleveland | E35: Michael | F35: McDaid | G35: GPO Box 586 | H35: - None - | I35: Sydney | J35: NSW | K35: 2000 | L35: Sydney | M35: NSW | N35: 2000 | O35: cleveland@mailplus.com.au | P35: Weekly | Q35: Current | R35: 1300656595 | S35: 42370 | U35: 0 | V35: No | W35: Yes | X35: 45609801194 | Y35: =IF(S35="","",($Y$1-S35)/365) -> 4.1123288 | AA35: =IF(Z35="","",ROUNDUP(Z35,0))
A36: 511913 | B36: NSW | C36: Coffs Harbour | D36: Coffs Harbour | E36: Julie | F36: Southam | G36: GPO Box 586 | H36: - None - | I36: Sydney | J36: NSW | K36: 2001 | L36: Sydney | M36: NSW | N36: 2001 | O36: coffsharbour@mailplus.com.au | P36: - None - | Q36: Current | R36: 416205346 | S36: 42370 | U36: 0 | V36: No | W36: Yes | X36: 45609801194 | Y36: =IF(S36="","",($Y$1-S36)/365) -> 4.1123288 | AA36: =IF(Z36="","",ROUNDUP(Z36,0))
A37: 671787 | B37: NSW | C37: Crows Nest | D37: Crows Nest | E37: Mark | F37: Phua | G37: - None - | H37: 32 Alexandra Street | I37: Hunters Hill | J37: NSW | K37: 2110 | L37: Hunters Hill | M37: NSW | N37: 2110 | O37: CrowsNest@mailplus.com.au | P37: Weekly | Q37: Current | R37: 422488988 | S37: 43556 | U37: 1 | V37: Yes | W37: No | X37: 98629003265 | Y37: =IF(S37="","",($Y$1-S37)/365) -> 0.8630137 | Z37: 0.8630137 | AA37: =IF(Z37="","",ROUNDUP(Z37,0)) -> 1
A38: 287 | B38: VIC | C38: Dandenong | D38: Dandenong | E38: Peter | F38: Sherer | G38: PO Box 5165 | H38: - None - | I38: Hallam | J38: VIC | K38: 3803 | L38: Upper Beaconsfield | M38: VIC | N38: 3808 | O38: dandenong@mailplus.com.au | P38: Weekly | Q38: Current | R38: 408557864 | S38: 38261 | T38: 43569 | U38: 4 | V38: Yes | W38: No | X38: 22006559244 | Y38: =IF(S38="","",($Y$1-S38)/365) -> 15.369863 | Z38: 15.369863 | AA38: =IF(Z38="","",ROUNDUP(Z38,0)) -> 16
A39: 228329 | B39: NSW | C39: Darlinghurst | D39: Darlinghurst | E39: John | F39: Rodao | G39: 8 Toplica Place | H39: - None - | I39: Canley Height | J39: NSW | K39: 2166 | L39: Canley Height | M39: NSW | N39: 2166 | O39: darlinghurst@mailplus.com.au | P39: Weekly | Q39: Current | R39: 414808031 | S39: 41901 | U39: 1 | V39: Yes | W39: No | X39: 79126483672 | Y39: =IF(S39="","",($Y$1-S39)/365) -> 5.3972603 | Z39: 5.3972603 | AA39: =IF(Z39="","",ROUNDUP(Z39,0)) -> 6
A40: 761281 | B40: NT | C40: Darwin | D40: Darwin | E40: S M Roman | F40: Kabir | G40: 82 Dripston Rd | H40: - None - | I40: Nakara | J40: NT | K40: 810 | L40: Nakara | M40: NT | N40: 810 | O40: darwin@mailplus.com.au | P40: Weekly | Q40: Current | R40: 426251103 | S40: 42370 | U40: 0 | V40: Yes | W40: No | X40: 70155020661 | Y40: =IF(S40="","",($Y$1-S40)/365) -> 4.1123288 | AA40: =IF(Z40="","",ROUNDUP(Z40,0))
...

Sheet Revenue @ Feb 2021
A1: Acacia Ridge | B1: 97298.54
A2: Adelaide CBD | B2: 161374.01
A3: Airport West | B3: 113990.49
A4: Albury | B4: 12981
A5: Alexandria | B5: 121031.34
A6: Altona | B6: 134658
A7: Arncliffe | B7: 107791.13
A8: Banyo | B8: 83599.26
A9: Barton | B9: 47125.17
A10: Baulkham Hills | B10: 183340.24
A11: Bayswater | B11: 59641.45
A12: Belmont | B12: 56049.27
... A132: Grand Total | B132: 15560889

Sheet Bondi 
A2: Franchisee | B2: Bondi Junction
A3: Franchisee Name | B3: Katy Brooks
A4: State | B4: NSW
A5: Profile
A6: Expiry Date | B6: 43909
A7: Ultimate Expiry Date (Including FY18 release) | B7: 47926
A8: Unlimted Term | B8: Yes
A9: Annual Turnover (service revenue) | B9: =VLOOKUP(B2,'[4]Revenue by Franchisee'!#REF!,2,0) -> #REF!
A10: Number of customers
A11: Number of customer using MPEX
A12: Digisitation | B12: YES
A13: Not in attendance at Roadshow | B13: NO
A14: Workshop Attendance | B14: YES
A15: Reading weekly bulletins(After final reminder) | B15: YES
A16: Customer Nomination | B16: NO
A17: MPEX allocation | B17: YES
A18: MPEX Usage % (as @ 08102019) | B18: =VLOOKUP(B2,'Franchisee Ranking'!#REF!,6,0) -> #REF!
A19: Late with completion of monthly invoicing | B19: NO
A20: Approved vehicle | B20: YES
A21: Vehicle signage (Past 4 years) | B21: YES
A22: Uniform (ordered in past 12months) | B22: ?
A23: HO Insurances | B23: YES
A24: 30th Sept action email (Feedback)

Sheet Scorecard summary
A1: Franchise | B1: Unlimited term candidated | C1: Franchisee Name | D1: State | E1: Profile | F1: Tenure | G1: Expiry Date | H1: FY22 Term candidate | I1: Ultimate Expiry Date (Including FY18 release) | J1: Unlimted Term | K1: Annual Turnover (service revenue) | L1: Digisitation | M1: Not in attendance at Roadshow | N1: Workshop Attendance | O1: Reading weekly bulletins(After final reminder) | P1: Customer Nomination | Q1: MPEX allocation | R1: MPEX Usage % (as @ 08102019) | S1: Late with completion of monthly invoicing | T1: Approved vehicle | U1: Vehicle signage (Past 4 years) | V1: Uniform (ordered in past 12months) | W1: HO Insurances | X1: 30th Sept action email (Feedback) | Y1: Terminated (mutually or otherwise) | Z1: Breach notice served | AA1: Written warning issued | AB1: commentary
A2: Coffs (HO Owned) | C2: MailPlus Head Office | D2: NSW | E2: N/A | F2: N/A | G2: N/A | I2: N/A | J2: HEAD OFFICE | K2: =VLOOKUP(A2,'Revenue @ Feb 2021'!A:B,2,0) -> #N/A | L2: YES | M2: YES | N2: YES | O2: YES | P2: NO | Q2: NO | S2: NO | T2: ? | U2: ? | V2: ? | W2: NO
